<?xml version="1.0" encoding="utf-8"?>
<!-- This URDF was automatically created by SolidWorks to URDF Exporter! Originally created by Stephen Brawner (brawner@gmail.com) 
     Commit Version: 1.6.0-4-g7f85cfe  Build Version: 1.6.7995.38578
     For more information, please see http://wiki.ros.org/sw_urdf_exporter -->
<robot
  name="M20">
  <link
    name="base_link">
    <inertial>
      <origin
        xyz="0.00000000 0.00000000 0.00000000"
        rpy="0 0 0" />
      <mass
        value="5.40000000" />
      <inertia
        ixx="0.05712348"
        ixy="0.00000000"
        ixz="0.00000000"
        iyy="0.20307764"
        iyz="0.00000000"
        izz="0.24210920" />
    </inertial>
    <visual>
      <origin
        xyz="0 0 0"
        rpy="0 0 0" />
      <geometry>
        <mesh
          filename="../meshes/base_link.STL" />
      </geometry>
      <material
        name="ironman_red">
        <color
          rgba="0.55 0.02 0.02 1" />
      </material>
    </visual>
    <collision>
      <origin
        xyz="0 0 0"
        rpy="0 0 0" />
      <geometry>
        <mesh
          filename="../meshes/base_link.STL" />
      </geometry>
    </collision>
  </link>
  <link
    name="fr_hipx">
    <inertial>
      <origin
        xyz="-0.00547403 -0.01777122 0.00000000"
        rpy="0 0 0" />
      <mass
        value="0.65000000" />
      <inertia
        ixx="0.00143521"
        ixy="0.00006323"
        ixz="0.00000000"
        iyy="0.00094994"
        iyz="0.00000000"
        izz="0.00152887" />
    </inertial>
    <visual>
      <origin
        xyz="0 0 0"
        rpy="0 0 0" />
      <geometry>
        <mesh
          filename="../meshes/fr_hipx.STL" />
      </geometry>
      <material
        name="ironman_gold">
        <color
          rgba="1.00 0.64 0.10 1" />
      </material>
    </visual>
    <collision>
      <origin
        xyz="0 0 0"
        rpy="0 0 0" />
      <geometry>
        <mesh
          filename="../meshes/fr_hipx.STL" />
      </geometry>
    </collision>
  </link>
  <joint
    name="fr_hipx_joint"
    type="revolute">
    <origin
      xyz="0.31 -0.135 0"
      rpy="0 0 0" />
    <parent
      link="base_link" />
    <child
      link="fr_hipx" />
    <axis
      xyz="-1 0 0" />
    <limit
      lower="-0.61"
      upper="0.44"
      effort="260.0"
      velocity="22.4" />
  </joint>
  <link
    name="fr_hipy">
    <inertial>
      <origin
        xyz="0.00000000 -0.11915921 -0.18259020"
        rpy="0 0 0" />
      <mass
        value="0.80000000" />
      <inertia
        ixx="0.00800669"
        ixy="0.00000000"
        ixz="0.00000000"
        iyy="0.00827645"
        iyz="-0.00084194"
        izz="0.00113314" />
    </inertial>
    <visual>
      <origin
        xyz="0 0 0"
        rpy="0 0 0" />
      <geometry>
        <mesh
          filename="../meshes/fr_hipy.STL" />
      </geometry>
      <material
        name="ironman_red">
        <color
          rgba="0.55 0.02 0.02 1" />
      </material>
    </visual>
    <collision>
      <origin
        xyz="0 0 0"
        rpy="0 0 0" />
      <geometry>
        <mesh
          filename="../meshes/fr_hipy.STL" />
      </geometry>
    </collision>
  </link>
  <joint
    name="fr_hipy_joint"
    type="revolute">
    <origin
      xyz="0 0 0"
      rpy="0 0 0" />
    <parent
      link="fr_hipx" />
    <child
      link="fr_hipy" />
    <axis
      xyz="0 -1 0" />
    <limit
      lower="-2.58"
      upper="2.29"
      effort="260.0"
      velocity="22.4" />
  </joint>
  <link
    name="fr_knee">
    <inertial>
      <origin
        xyz="0.00000000 -0.00255432 -0.18862470"
        rpy="0 0 0" />
      <mass
        value="0.80000000" />
      <inertia
        ixx="0.00753786"
        ixy="0.00000000"
        ixz="0.00000000"
        iyy="0.00783237"
        iyz="-0.00061560"
        izz="0.00101839" />
    </inertial>
    <visual>
      <origin
        xyz="0 0 0"
        rpy="0 0 0" />
      <geometry>
        <mesh
          filename="../meshes/fr_knee.STL" />
      </geometry>
      <material
        name="ironman_gold">
        <color
          rgba="1.00 0.64 0.10 1" />
      </material>
    </visual>
    <collision>
      <origin
        xyz="0 0 0"
        rpy="0 0 0" />
      <geometry>
        <mesh
          filename="../meshes/fr_knee.STL" />
      </geometry>
    </collision>
  </link>
  <joint
    name="fr_knee_joint"
    type="revolute">
    <origin
      xyz="0 -0.09 -0.25"
      rpy="0 0 0" />
    <parent
      link="fr_hipy" />
    <child
      link="fr_knee" />
    <axis
      xyz="0 -1 0" />
    <limit
      lower="-2.79"
      upper="2.81"
      effort="260.0"
      velocity="22.4" />
  </joint>
  <link
    name="fr_wheel">
    <inertial>
      <origin
        xyz="0.00000000 0.00000000 0.00000000"
        rpy="0 0 0" />
      <mass
        value="0.15000000" />
      <inertia
        ixx="0.00039500"
        ixy="0.00000000"
        ixz="0.00000000"
        iyy="0.00075000"
        iyz="0.00000000"
        izz="0.00039500" />
    </inertial>
    <visual>
      <origin
        xyz="0 0 0"
        rpy="0 0 0" />
      <geometry>
        <mesh
          filename="../meshes/fr_wheel.STL" />
      </geometry>
      <material
        name="dark_graphite">
        <color
          rgba="0.03 0.03 0.035 1" />
      </material>
    </visual>
    <collision>
      <origin
        xyz="0 0 0"
        rpy="0 0 0" />
      <geometry>
        <mesh
          filename="../meshes/fr_wheel.STL" />
      </geometry>
    </collision>
  </link>
  <joint
    name="fr_wheel_joint"
    type="continuous">
    <origin
      xyz="0 -0.07 -0.25"
      rpy="0 0 0" />
    <parent
      link="fr_knee" />
    <child
      link="fr_wheel" />
    <axis
      xyz="0 -1 0" />
    <limit
      effort="160.0"
      velocity="79.3" />
  </joint>
  <link
    name="fl_hipx">
    <inertial>
      <origin
        xyz="-0.00547403 0.01777122 0.00000000"
        rpy="0 0 0" />
      <mass
        value="0.65000000" />
      <inertia
        ixx="0.00143521"
        ixy="-0.00006323"
        ixz="0.00000000"
        iyy="0.00094994"
        iyz="0.00000000"
        izz="0.00152887" />
    </inertial>
    <visual>
      <origin
        xyz="0 0 0"
        rpy="0 0 0" />
      <geometry>
        <mesh
          filename="../meshes/fl_hipx.STL" />
      </geometry>
      <material
        name="ironman_gold">
        <color
          rgba="1.00 0.64 0.10 1" />
      </material>
    </visual>
    <collision>
      <origin
        xyz="0 0 0"
        rpy="0 0 0" />
      <geometry>
        <mesh
          filename="../meshes/fl_hipx.STL" />
      </geometry>
    </collision>
  </link>
  <joint
    name="fl_hipx_joint"
    type="revolute">
    <origin
      xyz="0.31 0.135 0"
      rpy="0 0 0" />
    <parent
      link="base_link" />
    <child
      link="fl_hipx" />
    <axis
      xyz="-1 0 0" />
    <limit
      lower="-0.44"
      upper="0.61"
      effort="260.0"
      velocity="22.4" />
  </joint>
  <link
    name="fl_hipy">
    <inertial>
      <origin
        xyz="0.00000000 0.11915922 -0.18259020"
        rpy="0 0 0" />
      <mass
        value="0.80000000" />
      <inertia
        ixx="0.00800669"
        ixy="0.00000000"
        ixz="0.00000000"
        iyy="0.00827645"
        iyz="0.00084194"
        izz="0.00113314" />
    </inertial>
    <visual>
      <origin
        xyz="0 0 0"
        rpy="0 0 0" />
      <geometry>
        <mesh
          filename="../meshes/fl_hipy.STL" />
      </geometry>
      <material
        name="ironman_red">
        <color
          rgba="0.55 0.02 0.02 1" />
      </material>
    </visual>
    <collision>
      <origin
        xyz="0 0 0"
        rpy="0 0 0" />
      <geometry>
        <mesh
          filename="../meshes/fl_hipy.STL" />
      </geometry>
    </collision>
  </link>
  <joint
    name="fl_hipy_joint"
    type="revolute">
    <origin
      xyz="0 0 0"
      rpy="0 0 0" />
    <parent
      link="fl_hipx" />
    <child
      link="fl_hipy" />
    <axis
      xyz="0 -1 0" />
    <limit
      lower="-2.58"
      upper="2.29"
      effort="260.0"
      velocity="22.4" />
  </joint>
  <link
    name="fl_knee">
    <inertial>
      <origin
        xyz="0.00000000 0.00255432 -0.18862470"
        rpy="0 0 0" />
      <mass
        value="0.80000000" />
      <inertia
        ixx="0.00753786"
        ixy="0.00000000"
        ixz="0.00000000"
        iyy="0.00783237"
        iyz="0.00061560"
        izz="0.00101839" />
    </inertial>
    <visual>
      <origin
        xyz="0 0 0"
        rpy="0 0 0" />
      <geometry>
        <mesh
          filename="../meshes/fl_knee.STL" />
      </geometry>
      <material
        name="ironman_gold">
        <color
          rgba="1.00 0.64 0.10 1" />
      </material>
    </visual>
    <collision>
      <origin
        xyz="0 0 0"
        rpy="0 0 0" />
      <geometry>
        <mesh
          filename="../meshes/fl_knee.STL" />
      </geometry>
    </collision>
  </link>
  <joint
    name="fl_knee_joint"
    type="revolute">
    <origin
      xyz="0 0.09 -0.25"
      rpy="0 0 0" />
    <parent
      link="fl_hipy" />
    <child
      link="fl_knee" />
    <axis
      xyz="0 -1 0" />
    <limit
      lower="-2.79"
      upper="2.81"
      effort="260.0"
      velocity="22.4" />
  </joint>
  <link
    name="fl_wheel">
    <inertial>
      <origin
        xyz="0.00000000 0.00000000 0.00000000"
        rpy="0 0 0" />
      <mass
        value="0.15000000" />
      <inertia
        ixx="0.00039500"
        ixy="0.00000000"
        ixz="0.00000000"
        iyy="0.00075000"
        iyz="0.00000000"
        izz="0.00039500" />
    </inertial>
    <visual>
      <origin
        xyz="0 0 0"
        rpy="0 0 0" />
      <geometry>
        <mesh
          filename="../meshes/fl_wheel.STL" />
      </geometry>
      <material
        name="dark_graphite">
        <color
          rgba="0.03 0.03 0.035 1" />
      </material>
    </visual>
    <collision>
      <origin
        xyz="0 0 0"
        rpy="0 0 0" />
      <geometry>
        <mesh
          filename="../meshes/fl_wheel.STL" />
      </geometry>
    </collision>
  </link>
  <joint
    name="fl_wheel_joint"
    type="continuous">
    <origin
      xyz="0 0.07 -0.25"
      rpy="0 0 0" />
    <parent
      link="fl_knee" />
    <child
      link="fl_wheel" />
    <axis
      xyz="0 -1 0" />
    <limit
      effort="160.0"
      velocity="79.3" />
  </joint>
  <link
    name="hr_hipx">
    <inertial>
      <origin
        xyz="0.00547403 -0.01777122 0.00000000"
        rpy="0 0 0" />
      <mass
        value="0.65000000" />
      <inertia
        ixx="0.00143521"
        ixy="-0.00006323"
        ixz="0.00000000"
        iyy="0.00094994"
        iyz="0.00000000"
        izz="0.00152887" />
    </inertial>
    <visual>
      <origin
        xyz="0 0 0"
        rpy="0 0 0" />
      <geometry>
        <mesh
          filename="../meshes/hr_hipx.STL" />
      </geometry>
      <material
        name="ironman_gold">
        <color
          rgba="1.00 0.64 0.10 1" />
      </material>
    </visual>
    <collision>
      <origin
        xyz="0 0 0"
        rpy="0 0 0" />
      <geometry>
        <mesh
          filename="../meshes/hr_hipx.STL" />
      </geometry>
    </collision>
  </link>
  <joint
    name="hr_hipx_joint"
    type="revolute">
    <origin
      xyz="-0.31 -0.135 0"
      rpy="0 0 0" />
    <parent
      link="base_link" />
    <child
      link="hr_hipx" />
    <axis
      xyz="-1 0 0" />
    <limit
      lower="-0.61"
      upper="0.44"
      effort="260.0"
      velocity="22.4" />
  </joint>
  <link
    name="hr_hipy">
    <inertial>
      <origin
        xyz="0.00000000 -0.11915921 -0.18259020"
        rpy="0 0 0" />
      <mass
        value="0.80000000" />
      <inertia
        ixx="0.00800669"
        ixy="0.00000000"
        ixz="0.00000000"
        iyy="0.00827645"
        iyz="-0.00084194"
        izz="0.00113314" />
    </inertial>
    <visual>
      <origin
        xyz="0 0 0"
        rpy="0 0 0" />
      <geometry>
        <mesh
          filename="../meshes/hr_hipy.STL" />
      </geometry>
      <material
        name="ironman_red">
        <color
          rgba="0.55 0.02 0.02 1" />
      </material>
    </visual>
    <collision>
      <origin
        xyz="0 0 0"
        rpy="0 0 0" />
      <geometry>
        <mesh
          filename="../meshes/hr_hipy.STL" />
      </geometry>
    </collision>
  </link>
  <joint
    name="hr_hipy_joint"
    type="revolute">
    <origin
      xyz="0 0 0"
      rpy="0 0 0" />
    <parent
      link="hr_hipx" />
    <child
      link="hr_hipy" />
    <axis
      xyz="0 -1 0" />
    <limit
      lower="-2.29"
      upper="2.58"
      effort="260.0"
      velocity="22.4" />
  </joint>
  <link
    name="hr_knee">
    <inertial>
      <origin
        xyz="0.00000000 -0.00255432 -0.18862470"
        rpy="0 0 0" />
      <mass
        value="0.80000000" />
      <inertia
        ixx="0.00753786"
        ixy="0.00000000"
        ixz="0.00000000"
        iyy="0.00783237"
        iyz="-0.00061560"
        izz="0.00101839" />
    </inertial>
    <visual>
      <origin
        xyz="0 0 0"
        rpy="0 0 0" />
      <geometry>
        <mesh
          filename="../meshes/hr_knee.STL" />
      </geometry>
      <material
        name="ironman_gold">
        <color
          rgba="1.00 0.64 0.10 1" />
      </material>
    </visual>
    <collision>
      <origin
        xyz="0 0 0"
        rpy="0 0 0" />
      <geometry>
        <mesh
          filename="../meshes/hr_knee.STL" />
      </geometry>
    </collision>
  </link>
  <joint
    name="hr_knee_joint"
    type="revolute">
    <origin
      xyz="0 -0.09 -0.25"
      rpy="0 0 0" />
    <parent
      link="hr_hipy" />
    <child
      link="hr_knee" />
    <axis
      xyz="0 -1 0" />
    <limit
      lower="-2.81"
      upper="2.79"
      effort="260.0"
      velocity="22.4" />
  </joint>
  <link
    name="hr_wheel">
    <inertial>
      <origin
        xyz="0.00000000 0.00000000 0.00000000"
        rpy="0 0 0" />
      <mass
        value="0.15000000" />
      <inertia
        ixx="0.00039500"
        ixy="0.00000000"
        ixz="0.00000000"
        iyy="0.00075000"
        iyz="0.00000000"
        izz="0.00039500" />
    </inertial>
    <visual>
      <origin
        xyz="0 0 0"
        rpy="0 0 0" />
      <geometry>
        <mesh
          filename="../meshes/hr_wheel.STL" />
      </geometry>
      <material
        name="dark_graphite">
        <color
          rgba="0.03 0.03 0.035 1" />
      </material>
    </visual>
    <collision>
      <origin
        xyz="0 0 0"
        rpy="0 0 0" />
      <geometry>
        <mesh
          filename="../meshes/hr_wheel.STL" />
      </geometry>
    </collision>
  </link>
  <joint
    name="hr_wheel_joint"
    type="continuous">
    <origin
      xyz="0 -0.07 -0.25"
      rpy="0 0 0" />
    <parent
      link="hr_knee" />
    <child
      link="hr_wheel" />
    <axis
      xyz="0 -1 0" />
    <limit
      effort="160.0"
      velocity="79.3" />
  </joint>
  <link
    name="hl_hipx">
    <inertial>
      <origin
        xyz="0.00547403 0.01777122 0.00000000"
        rpy="0 0 0" />
      <mass
        value="0.65000000" />
      <inertia
        ixx="0.00143521"
        ixy="0.00006323"
        ixz="0.00000000"
        iyy="0.00094994"
        iyz="0.00000000"
        izz="0.00152887" />
    </inertial>
    <visual>
      <origin
        xyz="0 0 0"
        rpy="0 0 0" />
      <geometry>
        <mesh
          filename="../meshes/hl_hipx.STL" />
      </geometry>
      <material
        name="ironman_gold">
        <color
          rgba="1.00 0.64 0.10 1" />
      </material>
    </visual>
    <collision>
      <origin
        xyz="0 0 0"
        rpy="0 0 0" />
      <geometry>
        <mesh
          filename="../meshes/hl_hipx.STL" />
      </geometry>
    </collision>
  </link>
  <joint
    name="hl_hipx_joint"
    type="revolute">
    <origin
      xyz="-0.31 0.135 0"
      rpy="0 0 0" />
    <parent
      link="base_link" />
    <child
      link="hl_hipx" />
    <axis
      xyz="-1 0 0" />
    <limit
      lower="-0.44"
      upper="0.61"
      effort="260.0"
      velocity="22.4" />
  </joint>
  <link
    name="hl_hipy">
    <inertial>
      <origin
        xyz="0.00000000 0.11915922 -0.18259020"
        rpy="0 0 0" />
      <mass
        value="0.80000000" />
      <inertia
        ixx="0.00800669"
        ixy="0.00000000"
        ixz="0.00000000"
        iyy="0.00827645"
        iyz="0.00084194"
        izz="0.00113314" />
    </inertial>
    <visual>
      <origin
        xyz="0 0 0"
        rpy="0 0 0" />
      <geometry>
        <mesh
          filename="../meshes/hl_hipy.STL" />
      </geometry>
      <material
        name="ironman_red">
        <color
          rgba="0.55 0.02 0.02 1" />
      </material>
    </visual>
    <collision>
      <origin
        xyz="0 0 0"
        rpy="0 0 0" />
      <geometry>
        <mesh
          filename="../meshes/hl_hipy.STL" />
      </geometry>
    </collision>
  </link>
  <joint
    name="hl_hipy_joint"
    type="revolute">
    <origin
      xyz="0 0 0"
      rpy="0 0 0" />
    <parent
      link="hl_hipx" />
    <child
      link="hl_hipy" />
    <axis
      xyz="0 -1 0" />
    <limit
      lower="-2.29"
      upper="2.58"
      effort="260.0"
      velocity="22.4" />
  </joint>
  <link
    name="hl_knee">
    <inertial>
      <origin
        xyz="0.00000000 0.00255432 -0.18862470"
        rpy="0 0 0" />
      <mass
        value="0.80000000" />
      <inertia
        ixx="0.00753786"
        ixy="0.00000000"
        ixz="0.00000000"
        iyy="0.00783237"
        iyz="0.00061560"
        izz="0.00101839" />
    </inertial>
    <visual>
      <origin
        xyz="0 0 0"
        rpy="0 0 0" />
      <geometry>
        <mesh
          filename="../meshes/hl_knee.STL" />
      </geometry>
      <material
        name="ironman_gold">
        <color
          rgba="1.00 0.64 0.10 1" />
      </material>
    </visual>
    <collision>
      <origin
        xyz="0 0 0"
        rpy="0 0 0" />
      <geometry>
        <mesh
          filename="../meshes/hl_knee.STL" />
      </geometry>
    </collision>
  </link>
  <joint
    name="hl_knee_joint"
    type="revolute">
    <origin
      xyz="0 0.09 -0.25"
      rpy="0 0 0" />
    <parent
      link="hl_hipy" />
    <child
      link="hl_knee" />
    <axis
      xyz="0 -1 0" />
    <limit
      lower="-2.81"
      upper="2.79"
      effort="260.0"
      velocity="22.4" />
  </joint>
  <link
    name="hl_wheel">
    <inertial>
      <origin
        xyz="0.00000000 0.00000000 0.00000000"
        rpy="0 0 0" />
      <mass
        value="0.15000000" />
      <inertia
        ixx="0.00039500"
        ixy="0.00000000"
        ixz="0.00000000"
        iyy="0.00075000"
        iyz="0.00000000"
        izz="0.00039500" />
    </inertial>
    <visual>
      <origin
        xyz="0 0 0"
        rpy="0 0 0" />
      <geometry>
        <mesh
          filename="../meshes/hl_wheel.STL" />
      </geometry>
      <material
        name="dark_graphite">
        <color
          rgba="0.03 0.03 0.035 1" />
      </material>
    </visual>
    <collision>
      <origin
        xyz="0 0 0"
        rpy="0 0 0" />
      <geometry>
        <mesh
          filename="../meshes/hl_wheel.STL" />
      </geometry>
    </collision>
  </link>
  <joint
    name="hl_wheel_joint"
    type="continuous">
    <origin
      xyz="0 0.07 -0.25"
      rpy="0 0 0" />
    <parent
      link="hl_knee" />
    <child
      link="hl_wheel" />
    <axis
      xyz="0 -1 0" />
    <limit
      effort="160.0"
      velocity="79.3" />
  </joint>
</robot>